Workbook

Sheet global part1 
A1: 바이어명 | B1: 업체명 | C1: 25년 1월 | D1: 25년 2월 | E1: 25년 3월 | F1: 25년 4월 | G1: 25년 5월 | H1: 25년 6월 | I1: 25년 7월 | J1: 25년 8월 | K1: 25년 8월 (~25일) | L1: 25년 9월 | M1: 25년 10월 | N1: 25년 11월 | O1: 25년 12월 | P1: 25년 합계 (~8월 25일) | Q1: 25년 합계 | R1: 26년 1월 | S1: 26년 2월 | T1: 26년 3월 | U1: 26년 4월 | V1: 26년 5월 | W1: 26년 6월 | X1: 26년 7월 | Y1: 26년 8월 (~25일) | Z1: 26년 9월 | AA1: 26년 10월 | AB1: 26년 11월 | AC1: 26년 12월 | AD1: 26년 합계 | AE1: 증감율 | AF1: 업체 순위
A2: POLO RALPH LAUREN | B2: HOISHUN KNITTING FACTORY LTD | C2: 44474140 | D2: 15862440 | E2: 34469800 | F2: 25013090 | G2: 23546510 | H2: 22370350 | I2: 22199490 | J2: 10770530 | K2: 10714940 | L2: 1216750 | M2: 113660 | N2: 416870 | O2: 1022070 | P2: =SUM(C2:I2,K2) -> 198650760 | Q2: =SUM(C2:J2,L2:O2) -> 201475700 | R2: 510760 | S2: 961080 | T2: 700570 | U2: 415280 | V2: 397760 | W2: 859410 | X2: 707250 | Y2: 282960 | AD2: =SUM(R2:AC2) -> 4835070 | AE2: =IF(OR(AD2="", P2=""), 0, IFERROR((AD2-P2)/P2, IF(AD2<>0, 1, 0))) -> -0.97566045 | AF2: =IFERROR(_xlfn.RANK.EQ(AD2, $AD$2:$AD$450), "") -> 86
A3: POLO RALPH LAUREN | B3: PT GOLDEN TEKSTIL INDONESIA | C3: 16690560 | D3: 13275460 | E3: 8158190 | F3: 4693000 | G3: 12475830 | H3: 12961520 | I3: 18170440 | J3: 10473190 | K3: 9289320 | L3: 8255470 | M3: 7764570 | N3: 13205210 | O3: 11372400 | P3: =SUM(C3:I3,K3) -> 95714320 | Q3: =SUM(C3:J3,L3:O3) -> 137495840 | R3: 18586130 | S3: 10993240 | T3: 9622830 | U3: 6668130 | V3: 6430680 | W3: 19945380 | X3: 21140190 | Y3: 10145380 | AD3: =SUM(R3:AC3) -> 103531960 | AE3: =IF(OR(AD3="", P3=""), 0, IFERROR((AD3-P3)/P3, IF(AD3<>0, 1, 0))) -> 0.081676807 | AF3: =IFERROR(_xlfn.RANK.EQ(AD3, $AD$2:$AD$450), "") -> 3 | AH3: 행 레이블 | AI3: 합계 : 25년 합계 | AJ3: 합계 : 26년 합계 | AK3: 증감수수료 | AL3: 증감율
A4: POLO RALPH LAUREN | B4: EVEREST TEXTILE CO., LTD. | C4: 14131110 | D4: 17518850 | E4: 6933840 | F4: 28530 | G4: 6666830 | H4: 3791420 | I4: 15110130 | J4: 16886690 | K4: 15459030 | L4: 4896580 | M4: 856960 | N4: 2461540 | O4: 6558550 | P4: =SUM(C4:I4,K4) -> 79639740 | Q4: =SUM(C4:J4,L4:O4) -> 95841030 | AD4: =SUM(R4:AC4) -> 0 | AE4: =IF(OR(AD4="", P4=""), 0, IFERROR((AD4-P4)/P4, IF(AD4<>0, 1, 0))) -> -1 | AF4: =IFERROR(_xlfn.RANK.EQ(AD4, $AD$2:$AD$450), "") -> 240 | AH4: POLO RALPH LAUREN | AI4: 2045178760 | AJ4: 2151983580 | AK4: =AJ4-AI4 -> 106804820 | AL4: =IFERROR((AJ4-AI4)/AI4, 0) -> 0.052222731
A5: POLO RALPH LAUREN | B5: FAR EASTERN NEW CENTURY CORPORATION | C5: 15986780 | D5: 7538350 | E5: 3887980 | F5: 10581020 | G5: 5531620 | H5: 5327840 | I5: 13136920 | J5: 9332600 | K5: 9332600 | L5: 7494900 | M5: 1479890 | N5: 2913150 | O5: 9400480 | P5: =SUM(C5:I5,K5) -> 71323110 | Q5: =SUM(C5:J5,L5:O5) -> 92611530 | R5: 12285500 | S5: 1708520 | T5: 470250 | U5: 5990660 | V5: 2644840 | W5: 5091030 | X5: 10595520 | Y5: 11577840 | AD5: =SUM(R5:AC5) -> 50364160 | AE5: =IF(OR(AD5="", P5=""), 0, IFERROR((AD5-P5)/P5, IF(AD5<>0, 1, 0))) -> -0.29385917 | AF5: =IFERROR(_xlfn.RANK.EQ(AD5, $AD$2:$AD$450), "") -> 10 | AH5: CLUB MONACO | AI5: 82200330 | AJ5: 7778920 | AK5: =AJ5-AI5 -> -74421410 | AL5: =IFERROR((AJ5-AI5)/AI5, 0) -> -0.90536632
A6: POLO RALPH LAUREN | B6: Tung Ga Linen & Cotton Mills Ltd | C6: 15180360 | D6: 8516380 | E6: 4456510 | F6: 6242560 | G6: 5693690 | H6: 6777850 | I6: 18247080 | J6: 15555490 | K6: 13671140 | L6: 15755600 | M6: 17455270 | N6: 16431460 | O6: 10691210 | P6: =SUM(C6:I6,K6) -> 78785570 | Q6: =SUM(C6:J6,L6:O6) -> 141003460 | R6: 7671930 | S6: 1034210 | T6: 3518160 | U6: 1701540 | V6: 1039860 | W6: 0 | X6: 1723450 | Y6: 1260020 | AD6: =SUM(R6:AC6) -> 17949170 | AE6: =IF(OR(AD6="", P6=""), 0, IFERROR((AD6-P6)/P6, IF(AD6<>0, 1, 0))) -> -0.77217694 | AF6: =IFERROR(_xlfn.RANK.EQ(AD6, $AD$2:$AD$450), "") -> 29 | AH6: 총합계 | AI6: 2127379090 | AJ6: 2159762500 | AK6: =AJ6-AI6 -> 32383410 | AL6: =IFERROR((AJ6-AI6)/AI6, 0) -> 0.015222209
A7: POLO RALPH LAUREN | B7: Ruentex industries limited | C7: 14541130 | D7: 8445290 | E7: 4831320 | F7: 3768800 | G7: 7786340 | H7: 6478680 | I7: 14625220 | J7: 3124700 | K7: 3124700 | L7: 4402460 | M7: 3419020 | N7: 4069100 | O7: 6241730 | P7: =SUM(C7:I7,K7) -> 63601480 | Q7: =SUM(C7:J7,L7:O7) -> 81733790 | R7: 9318640 | S7: 7489610 | T7: 4076860 | U7: 7488300 | V7: 11164660 | W7: 6976450 | X7: 14818420 | Y7: 9054260 | AD7: =SUM(R7:AC7) -> 70387200 | AE7: =IF(OR(AD7="", P7=""), 0, IFERROR((AD7-P7)/P7, IF(AD7<>0, 1, 0))) -> 0.10669123 | AF7: =IFERROR(_xlfn.RANK.EQ(AD7, $AD$2:$AD$450), "") -> 5
A8: POLO RALPH LAUREN | B8: Skytrend Co.Ltd | C8: 5727760 | D8: 16017580 | E8: 8306740 | F8: 837410 | G8: 7537330 | H8: 934160 | I8: 5762310 | J8: 6418550 | K8: 3716390 | L8: 0 | M8: 0 | N8: 0 | O8: 0 | P8: =SUM(C8:I8,K8) -> 48839680 | Q8: =SUM(C8:J8,L8:O8) -> 51541840 | S8: 797410 | T8: 0 | U8: 0 | V8: 0 | W8: 0 | X8: 0 | Y8: 0 | AD8: =SUM(R8:AC8) -> 797410 | AE8: =IF(OR(AD8="", P8=""), 0, IFERROR((AD8-P8)/P8, IF(AD8<>0, 1, 0))) -> -0.98367291 | AF8: =IFERROR(_xlfn.RANK.EQ(AD8, $AD$2:$AD$450), "") -> 165
A9: POLO RALPH LAUREN | B9: BONDEX TEXTILES LIMITED | C9: 7736960 | D9: 6277020 | E9: 5056030 | F9: 8112840 | G9: 8749440 | H9: 9041450 | I9: 13835760 | J9: 7241000 | K9: 5939260 | L9: 1605580 | M9: 75740 | N9: 41680 | O9: 143030 | P9: =SUM(C9:I9,K9) -> 64748760 | Q9: =SUM(C9:J9,L9:O9) -> 67916530 | T9: 40590 | U9: 30140 | V9: 42850 | W9: 0 | X9: 330440 | Y9: 97160 | AD9: =SUM(R9:AC9) -> 541180 | AE9: =IF(OR(AD9="", P9=""), 0, IFERROR((AD9-P9)/P9, IF(AD9<>0, 1, 0))) -> -0.99164185 | AF9: =IFERROR(_xlfn.RANK.EQ(AD9, $AD$2:$AD$450), "") -> 174
A10: POLO RALPH LAUREN | B10: HIGH HOPE AGLORY LTD | C10: 2690010 | D10: 318350 | E10: 4463330 | F10: 1212790 | G10: 26074630 | H10: 4413740 | I10: 4590860 | J10: 1235020 | K10: 1235020 | L10: 0 | M10: 238320 | N10: 376500 | O10: 29370 | P10: =SUM(C10:I10,K10) -> 44998730 | Q10: =SUM(C10:J10,L10:O10) -> 45642920 | S10: 2012520 | T10: 2708180 | U10: 8953010 | V10: 17660960 | W10: 6678400 | X10: 30630 | Y10: 0 | AD10: =SUM(R10:AC10) -> 38043700 | AE10: =IF(OR(AD10="", P10=""), 0, IFERROR((AD10-P10)/P10, IF(AD10<>0, 1, 0))) -> -0.15456058 | AF10: =IFERROR(_xlfn.RANK.EQ(AD10, $AD$2:$AD$450), "") -> 16
A11: POLO RALPH LAUREN | B11: KA TSUN INDUSTRIAL (INTERNATIONAL)COMPANY LTD | C11: 9894460 | D11: 2698600 | E11: 9367930 | F11: 1625890 | G11: 4286670 | H11: 2112980 | I11: 4560830 | J11: 3312730 | K11: 2540870 | L11: 1131100 | M11: 1608910 | N11: 1870790 | O11: 6708020 | P11: =SUM(C11:I11,K11) -> 37088230 | Q11: =SUM(C11:J11,L11:O11) -> 49178910 | R11: 5913800 | S11: 2117510 | T11: 8579520 | U11: 2343460 | V11: 782860 | W11: 4068150 | X11: 5974420 | Y11: 4202510 | AD11: =SUM(R11:AC11) -> 33982230 | AE11: =IF(OR(AD11="", P11=""), 0, IFERROR((AD11-P11)/P11, IF(AD11<>0, 1, 0))) -> -0.083746245 | AF11: =IFERROR(_xlfn.RANK.EQ(AD11, $AD$2:$AD$450), "") -> 19
A12: POLO RALPH LAUREN | B12: ZHANGJIAGANG JINLING TEXTILES CO | P12: =SUM(C12:I12,K12) -> 0 | Q12: =SUM(C12:J12,L12:O12) -> 0 | AD12: =SUM(R12:AC12) -> 0 | AE12: =IF(OR(AD12="", P12=""), 0, IFERROR((AD12-P12)/P12, IF(AD12<>0, 1, 0))) -> 0 | AF12: =IFERROR(_xlfn.RANK.EQ(AD12, $AD$2:$AD$450), "") -> 240
A13: POLO RALPH LAUREN | B13: Tin Fook Knitting Accessories Limited | C13: 7412860 | D13: 1527140 | E13: 11093560 | F13: 5265660 | G13: 2376770 | H13: 4932930 | I13: 1368940 | J13: 746370 | K13: 746370 | L13: 5959750 | M13: 3467570 | N13: 5281180 | O13: 10939740 | P13: =SUM(C13:I13,K13) -> 34724230 | Q13: =SUM(C13:J13,L13:O13) -> 60372470 | R13: 15987450 | S13: 1462920 | T13: 2033470 | U13: 6664210 | V13: 4915940 | W13: 2369020 | X13: 4875980 | Y13: 5025190 | AD13: =SUM(R13:AC13) -> 43334180 | AE13: =IF(OR(AD13="", P13=""), 0, IFERROR((AD13-P13)/P13, IF(AD13<>0, 1, 0))) -> 0.24795222 | AF13: =IFERROR(_xlfn.RANK.EQ(AD13, $AD$2:$AD$450), "") -> 14
A14: POLO RALPH LAUREN | B14: CHI HING ELASTIC WEAVING FTY LTD | C14: 5703430 | D14: 5815150 | E14: 5232380 | F14: 5495790 | G14: 3972650 | H14: 4942610 | I14: 5448920 | J14: 4821820 | K14: 4025400 | L14: 3928180 | M14: 2797150 | N14: 2048860 | O14: 8179030 | P14: =SUM(C14:I14,K14) -> 40636330 | Q14: =SUM(C14:J14,L14:O14) -> 58385970 | R14: 6985390 | S14: 1371150 | T14: 3476160 | U14: 5525200 | V14: 4203580 | W14: 6317620 | X14: 11468310 | Y14: 5368490 | AD14: =SUM(R14:AC14) -> 44715900 | AE14: =IF(OR(AD14="", P14=""), 0, IFERROR((AD14-P14)/P14, IF(AD14<>0, 1, 0))) -> 0.10039219 | AF14: =IFERROR(_xlfn.RANK.EQ(AD14, $AD$2:$AD$450), "") -> 12
A15: POLO RALPH LAUREN | B15: Bigger Textile Holdings Limited | C15: 4662880 | D15: 0 | E15: 6664850 | F15: 7658560 | G15: 3135920 | H15: 1533380 | I15: 4186050 | J15: 603640 | K15: 603640 | L15: 41680 | M15: 43090 | N15: 592330 | O15: 2976610 | P15: =SUM(C15:I15,K15) -> 28445280 | Q15: =SUM(C15:J15,L15:O15) -> 32098990 | R15: 8749800 | S15: 498530 | T15: 6056020 | U15: 5697690 | V15: 6465090 | W15: 3943320 | X15: 2782390 | Y15: 255360 | AD15: =SUM(R15:AC15) -> 34448200 | AE15: =IF(OR(AD15="", P15=""), 0, IFERROR((AD15-P15)/P15, IF(AD15<>0, 1, 0))) -> 0.21103396 | AF15: =IFERROR(_xlfn.RANK.EQ(AD15, $AD$2:$AD$450), "") -> 18
A16: POLO RALPH LAUREN | B16: TAKIHYO Co.,Ltd. | C16: 2167860 | D16: 3128030 | E16: 8026720 | F16: 4723620 | G16: 3019360 | H16: 6604870 | I16: 5806510 | J16: 2937530 | K16: 2631160 | L16: 6394470 | M16: 5435560 | N16: 6707020 | O16: 4743910 | P16: =SUM(C16:I16,K16) -> 36108130 | Q16: =SUM(C16:J16,L16:O16) -> 59695460 | R16: 3506430 | S16: 4767690 | T16: 3790660 | U16: 6345700 | V16: 6226300 | W16: 3496010 | X16: 11159740 | Y16: 6347860 | AD16: =SUM(R16:AC16) -> 45640390 | AE16: =IF(OR(AD16="", P16=""), 0, IFERROR((AD16-P16)/P16, IF(AD16<>0, 1, 0))) -> 0.26399207 | AF16: =IFERROR(_xlfn.RANK.EQ(AD16, $AD$2:$AD$450), "") -> 11
A17: POLO RALPH LAUREN | B17: COPEN UNITED LIMITED | C17: 6867400 | D17: 4005050 | E17: 2333850 | F17: 5050560 | G17: 2674990 | H17: 4303340 | I17: 2471290 | J17: 3787700 | K17: 3423250 | L17: 7057310 | M17: 2223340 | N17: 2382660 | O17: 3762160 | P17: =SUM(C17:I17,K17) -> 31129730 | Q17: =SUM(C17:J17,L17:O17) -> 46919650 | R17: 4657010 | S17: 2382180 | T17: 1541130 | U17: 2062170 | V17: 0 | W17: 0 | X17: 2610980 | Y17: 0 | AD17: =SUM(R17:AC17) -> 13253470 | AE17: =IF(OR(AD17="", P17=""), 0, IFERROR((AD17-P17)/P17, IF(AD17<>0, 1, 0))) -> -0.5742504 | AF17: =IFERROR(_xlfn.RANK.EQ(AD17, $AD$2:$AD$450), "") -> 40
A18: POLO RALPH LAUREN | B18: Unifield Textiles Limited | C18: 4211080 | D18: 4038840 | E18: 4800850 | F18: 3819470 | G18: 1867220 | H18: 1290690 | I18: 4237570 | J18: 1658060 | K18: 1309710 | L18: 3052420 | M18: 4948550 | N18: 1675580 | O18: 4476510 | P18: =SUM(C18:I18,K18) -> 25575430 | Q18: =SUM(C18:J18,L18:O18) -> 40076840 | R18: 6120670 | S18: 1769900 | T18: 4824520 | U18: 5099210 | V18: 2432350 | W18: 2722640 | X18: 3571190 | Y18: 4828150 | AD18: =SUM(R18:AC18) -> 31368630 | AE18: =IF(OR(AD18="", P18=""), 0, IFERROR((AD18-P18)/P18, IF(AD18<>0, 1, 0))) -> 0.22651428 | AF18: =IFERROR(_xlfn.RANK.EQ(AD18, $AD$2:$AD$450), "") -> 20
A19: POLO RALPH LAUREN | B19: Dongguan Yitao Textile Co Ltd | C19: 7876990 | D19: 216670 | E19: 3402360 | F19: 2836550 | G19: 3914960 | H19: ARANKNIT SRL | I19: 13834320 | J19: 3307010 | K19: 2999560 | L19: 5215390 | M19: 585990 | N19: 1450090 | O19: 3737500 | P19: =SUM(C19:I19,K19) -> 35081410 | Q19: =SUM(C19:J19,L19:O19) -> 46377830 | R19: 10371040 | S19: 3899220 | T19: 5511660 | U19: 2460440 | V19: 3121190 | W19: 12096310 | X19: 5399910 | Y19: 8511200 | AD19: =SUM(R19:AC19) -> 51370970 | AE19: =IF(OR(AD19="", P19=""), 0, IFERROR((AD19-P19)/P19, IF(AD19<>0, 1, 0))) -> 0.46433595 | AF19: =IFERROR(_xlfn.RANK.EQ(AD19, $AD$2:$AD$450), "") -> 9
A20: POLO RALPH LAUREN | B20: KWAN TAT INDUSTRIAL LTD | C20: 7214660 | D20: 1940510 | E20: 2775000 | F20: 1329480 | G20: 4687530 | H20: 7749540 | I20: 13830430 | J20: 3895760 | K20: 3743020 | L20: 1211250 | M20: 1039380 | N20: 4469700 | O20: 12281690 | P20: =SUM(C20:I20,K20) -> 43270170 | Q20: =SUM(C20:J20,L20:O20) -> 62424930 | R20: 3523490 | S20: 498160 | T20: 2874160 | U20: 547310 | V20: 744720 | W20: 5445400 | X20: 9795240 | Y20: 6366580 | AD20: =SUM(R20:AC20) -> 29795060 | AE20: =IF(OR(AD20="", P20=""), 0, IFERROR((AD20-P20)/P20, IF(AD20<>0, 1, 0))) -> -0.311418 | AF20: =IFERROR(_xlfn.RANK.EQ(AD20, $AD$2:$AD$450), "") -> 21
A21: POLO RALPH LAUREN | B21: PONIE SG PTE LTD. | C21: 9432920 | D21: 3452290 | E21: 981490 | F21: 335450 | G21: 594720 | H21: 0 | I21: 0 | J21: 1565540 | K21: 1565540 | L21: 0 | M21: 1144960 | N21: 0 | O21: 0 | P21: =SUM(C21:I21,K21) -> 16362410 | Q21: =SUM(C21:J21,L21:O21) -> 17507370 | AD21: =SUM(R21:AC21) -> 0 | AE21: =IF(OR(AD21="", P21=""), 0, IFERROR((AD21-P21)/P21, IF(AD21<>0, 1, 0))) -> -1 | AF21: =IFERROR(_xlfn.RANK.EQ(AD21, $AD$2:$AD$450), "") -> 240
A22: POLO RALPH LAUREN | B22: Highfashion(China) Co., Ltd | C22: 1522090 | D22: 1361120 | E22: 6349010 | F22: 5637650 | G22: 1623250 | H22: 2313570 | I22: 3575040 | J22: 3621870 | K22: 3538560 | L22: 5233310 | M22: 2022030 | N22: 934720 | O22: 1746360 | P22: =SUM(C22:I22,K22) -> 25920290 | Q22: =SUM(C22:J22,L22:O22) -> 35940020 | R22: 3716170 | S22: 955270 | T22: 1954360 | U22: 2387070 | V22: 955310 | W22: 407210 | X22: 4109220 | Y22: 1870990 | AD22: =SUM(R22:AC22) -> 16355600 | AE22: =IF(OR(AD22="", P22=""), 0, IFERROR((AD22-P22)/P22, IF(AD22<>0, 1, 0))) -> -0.36900397 | AF22: =IFERROR(_xlfn.RANK.EQ(AD22, $AD$2:$AD$450), "") -> 31
A23: POLO RALPH LAUREN | B23: TOB TEXTILE LIMITED | C23: 4137100 | D23: 1740080 | E23: 4289940 | F23: 1491560 | G23: 3559960 | H23: 3994720 | I23: 1425000 | J23: 1559210 | K23: 1559210 | L23: 2416320 | M23: 1029930 | N23: 4762040 | O23: 3689050 | P23: =SUM(C23:I23,K23) -> 22197570 | Q23: =SUM(C23:J23,L23:O23) -> 34094910 | R23: 3656070 | S23: 28910 | T23: 2346700 | U23: 1836080 | V23: 5629850 | W23: 1416470 | X23: 1394360 | Y23: 2305630 | AD23: =SUM(R23:AC23) -> 18614070 | AE23: =IF(OR(AD23="", P23=""), 0, IFERROR((AD23-P23)/P23, IF(AD23<>0, 1, 0))) -> -0.16143659 | AF23: =IFERROR(_xlfn.RANK.EQ(AD23, $AD$2:$AD$450), "") -> 28
A24: POLO RALPH LAUREN | B24: Jasmine Industrial Ltd | C24: 5855260 | D24: 2067000 | E24: 3249950 | F24: 1799350 | G24: 1536830 | H24: 1486470 | I24: 1740270 | J24: 1684350 | L24: 3067020 | M24: 1676630 | N24: 3062820 | O24: 1914670 | P24: =SUM(C24:I24,K24) -> 17735130 | Q24: =SUM(C24:J24,L24:O24) -> 29140620 | R24: 2093100 | S24: 3082150 | T24: 4375960 | AD24: =SUM(R24:AC24) -> 9551210 | AE24: =IF(OR(AD24="", P24=""), 0, IFERROR((AD24-P24)/P24, IF(AD24<>0, 1, 0))) -> -0.4614525 | AF24: =IFERROR(_xlfn.RANK.EQ(AD24, $AD$2:$AD$450), "") -> 52
A25: POLO RALPH LAUREN | B25: De Lenis Limited | C25: 5890010 | D25: 657210 | E25: 2343960 | F25: 2370700 | G25: 1879490 | H25: 2505020 | I25: 6270700 | J25: 1302820 | K25: 1150270 | L25: 6131210 | M25: 3594820 | N25: 1482480 | O25: 4985120 | P25: =SUM(C25:I25,K25) -> 23067360 | Q25: =SUM(C25:J25,L25:O25) -> 39413540 | R25: 6870820 | S25: 1925980 | T25: 1523310 | U25: 7874930 | V25: 4314850 | W25: 8231950 | X25: 22442580 | Y25: 6682650 | AD25: =SUM(R25:AC25) -> 59867070 | AE25: =IF(OR(AD25="", P25=""), 0, IFERROR((AD25-P25)/P25, IF(AD25<>0, 1, 0))) -> 1.5953152 | AF25: =IFERROR(_xlfn.RANK.EQ(AD25, $AD$2:$AD$450), "") -> 7
A26: POLO RALPH LAUREN | B26: Jiaxing Wanhong Textile CO.LTD | C26: 1831440 | D26: 811160 | E26: 4392520 | F26: 2197390 | G26: 3438870 | H26: 3905510 | I26: 2005150 | J26: 3112440 | K26: 3056800 | L26: 5346050 | M26: 2219340 | N26: 5782680 | O26: 4504960 | P26: =SUM(C26:I26,K26) -> 21638840 | Q26: =SUM(C26:J26,L26:O26) -> 39547510 | R26: 1533060 | S26: 382260 | T26: 4205340 | U26: 9272090 | V26: 5506550 | W26: 7580700 | X26: 2830800 | Y26: 5793690 | AD26: =SUM(R26:AC26) -> 37104490 | AE26: =IF(OR(AD26="", P26=""), 0, IFERROR((AD26-P26)/P26, IF(AD26<>0, 1, 0))) -> 0.71471715 | AF26: =IFERROR(_xlfn.RANK.EQ(AD26, $AD$2:$AD$450), "") -> 17
A27: POLO RALPH LAUREN | B27: TAT FUNG TEXTILE COMPANY LIMITED | C27: 1754710 | D27: 2333940 | E27: 2271820 | F27: 1931040 | G27: 3745280 | H27: 784950 | I27: 3561430 | J27: 4260750 | K27: 3903880 | L27: 1550740 | M27: 3047530 | N27: 1567990 | O27: 3082830 | P27: =SUM(C27:I27,K27) -> 20287050 | Q27: =SUM(C27:J27,L27:O27) -> 29893010 | R27: 1274330 | S27: 400060 | T27: 2976870 | U27: 1455950 | V27: 3658230 | W27: 3187370 | X27: 6752790 | Y27: 2567180 | AD27: =SUM(R27:AC27) -> 22272780 | AE27: =IF(OR(AD27="", P27=""), 0, IFERROR((AD27-P27)/P27, IF(AD27<>0, 1, 0))) -> 0.097881654 | AF27: =IFERROR(_xlfn.RANK.EQ(AD27, $AD$2:$AD$450), "") -> 26
A28: POLO RALPH LAUREN | B28: NANTONG FOREMOST GARMENT & ACCESSORIES CO LTD | D28: 0 | E28: 0 | F28: 10350090 | G28: 1236980 | H28: 688380 | I28: 0 | J28: 0 | K28: 0 | L28: 0 | M28: 1190800 | N28: 12064400 | O28: 29310 | P28: =SUM(C28:I28,K28) -> 12275450 | Q28: =SUM(C28:J28,L28:O28) -> 25559960 | U28: 21191310 | V28: 3159080 | W28: 60510 | X28: 0 | Y28: 0 | AD28: =SUM(R28:AC28) -> 24410900 | AE28: =IF(OR(AD28="", P28=""), 0, IFERROR((AD28-P28)/P28, IF(AD28<>0, 1, 0))) -> 0.98859512 | AF28: =IFERROR(_xlfn.RANK.EQ(AD28, $AD$2:$AD$450), "") -> 22
A29: POLO RALPH LAUREN | B29: MORITO SCOVILL HK CO. LTD | C29: 1334950 | D29: 1267480 | E29: 6483880 | F29: 1486670 | G29: 1052670 | H29: 927190 | I29: 1201570 | J29: 1405760 | K29: 1054000 | L29: 1020860 | M29: 2885170 | N29: 2377070 | O29: 0 | P29: =SUM(C29:I29,K29) -> 14808410 | Q29: =SUM(C29:J29,L29:O29) -> 21443270 | U29: 318010 | V29: 0 | W29: 0 | X29: 0 | Y29: 0 | AD29: =SUM(R29:AC29) -> 318010 | AE29: =IF(OR(AD29="", P29=""), 0, IFERROR((AD29-P29)/P29, IF(AD29<>0, 1, 0))) -> -0.97852504 | AF29: =IFERROR(_xlfn.RANK.EQ(AD29, $AD$2:$AD$450), "") -> 193
A30: POLO RALPH LAUREN | B30: 0 Mile Corp | C30: 1532540 | D30: 689700 | E30: 1938110 | F30: 2716170 | G30: 4397960 | H30: 2435910 | I30: 5346970 | J30: 1369310 | K30: 1232980 | L30: 146970 | M30: 1347630 | N30: 1459810 | O30: 7129350 | P30: =SUM(C30:I30,K30) -> 20290340 | Q30: =SUM(C30:J30,L30:O30) -> 30510430 | R30: 3884440 | S30: 2125770 | T30: 1622370 | U30: 8702980 | V30: 7947970 | W30: 1615700 | X30: 10647960 | Y30: 2161980 | AD30: =SUM(R30:AC30) -> 38709170 | AE30: =IF(OR(AD30="", P30=""), 0, IFERROR((AD30-P30)/P30, IF(AD30<>0, 1, 0))) -> 0.9077635 | AF30: =IFERROR(_xlfn.RANK.EQ(AD30, $AD$2:$AD$450), "") -> 15
A31: POLO RALPH LAUREN | B31: LMH FASHION LIMITED | C31: 3052390 | D31: 907840 | E31: 515360 | F31: 3394300 | G31: 2498380 | H31: 2033910 | I31: 2796360 | J31: 1198390 | L31: 752460 | M31: 1696360 | N31: 2066790 | O31: 2675960 | P31: =SUM(C31:I31,K31) -> 15198540 | Q31: =SUM(C31:J31,L31:O31) -> 23588500 | R31: 1423890 | S31: 29400 | AD31: =SUM(R31:AC31) -> 1453290 | AE31: =IF(OR(AD31="", P31=""), 0, IFERROR((AD31-P31)/P31, IF(AD31<>0, 1, 0))) -> -0.90437963 | AF31: =IFERROR(_xlfn.RANK.EQ(AD31, $AD$2:$AD$450), "") -> 134
A32: POLO RALPH LAUREN | B32: Sunline Sankei Yokohama (H.K) Co, Ltd | C32: 5317820 | D32: 871750 | E32: 2832260 | F32: 975720 | G32: 0 | H32: 0 | I32: 825200 | J32: 2527740 | K32: 2198650 | L32: 875300 | M32: 447260 | N32: 0 | O32: 1443930 | P32: =SUM(C32:I32,K32) -> 13021400 | Q32: =SUM(C32:J32,L32:O32) -> 16116980 | S32: 540750 | T32: 359770 | U32: 0 | V32: 1654460 | W32: 0 | X32: 0 | Y32: 421760 | AD32: =SUM(R32:AC32) -> 2976740 | AE32: =IF(OR(AD32="", P32=""), 0, IFERROR((AD32-P32)/P32, IF(AD32<>0, 1, 0))) -> -0.77139632 | AF32: =IFERROR(_xlfn.RANK.EQ(AD32, $AD$2:$AD$450), "") -> 111
A33: POLO RALPH LAUREN | B33: suzhou unitedtex enterprise ltd | C33: 1514850 | D33: 504280 | E33: 1957030 | F33: 5051680 | G33: 970600 | H33: 1873610 | I33: 1108390 | J33: 679750 | K33: 679750 | L33: 1811540 | M33: 390230 | N33: 1795630 | O33: 4695430 | P33: =SUM(C33:I33,K33) -> 13660190 | Q33: =SUM(C33:J33,L33:O33) -> 22353020 | R33: 2886970 | S33: 223580 | T33: 2358110 | U33: 1571060 | V33: 2940200 | W33: 4853610 | X33: 3567220 | Y33: 1219630 | AD33: =SUM(R33:AC33) -> 19620380 | AE33: =IF(OR(AD33="", P33=""), 0, IFERROR((AD33-P33)/P33, IF(AD33<>0, 1, 0))) -> 0.43631824 | AF33: =IFERROR(_xlfn.RANK.EQ(AD33, $AD$2:$AD$450), "") -> 27
A34: POLO RALPH LAUREN | B34: Shimada Shoji (H.K.) Limited | C34: 3558480 | D34: 233170 | E34: 1682860 | F34: 3421710 | G34: 587880 | H34: 1063320 | I34: 7106780 | J34: 4345750 | K34: 4008000 | L34: 1600570 | M34: 2111720 | N34: 6273400 | O34: 3466680 | P34: =SUM(C34:I34,K34) -> 21662200 | Q34: =SUM(C34:J34,L34:O34) -> 35452320 | R34: 1677300 | S34: 94810 | T34: 371400 | U34: 0 | V34: 2238810 | W34: 620760 | X34: 618990 | Y34: 2194990 | AD34: =SUM(R34:AC34) -> 7817060 | AE34: =IF(OR(AD34="", P34=""), 0, IFERROR((AD34-P34)/P34, IF(AD34<>0, 1, 0))) -> -0.63913822 | AF34: =IFERROR(_xlfn.RANK.EQ(AD34, $AD$2:$AD$450), "") -> 65
A35: POLO RALPH LAUREN | B35: BESTLINING LIMITED | C35: 5118130 | D35: 1415090 | E35: 2090870 | F35: 0 | G35: 0 | H35: 0 | I35: 0 | J35: 0 | K35: 0 | L35: 0 | M35: 0 | N35: 0 | O35: 0 | P35: =SUM(C35:I35,K35) -> 8624090 | Q35: =SUM(C35:J35,L35:O35) -> 8624090 | AD35: =SUM(R35:AC35) -> 0 | AE35: =IF(OR(AD35="", P35=""), 0, IFERROR((AD35-P35)/P35, IF(AD35<>0, 1, 0))) -> -1 | AF35: =IFERROR(_xlfn.RANK.EQ(AD35, $AD$2:$AD$450), "") -> 240
A36: POLO RALPH LAUREN | B36: Win Square International Ltd. | C36: 1326190 | D36: 814300 | E36: 1357600 | F36: 3236320 | G36: 1778170 | H36: 1025840 | I36: 4370230 | J36: 1859410 | K36: 1831500 | L36: 1873910 | M36: 1481810 | N36: 0 | O36: 1960060 | P36: =SUM(C36:I36,K36) -> 15740150 | Q36: =SUM(C36:J36,L36:O36) -> 21083840 | R36: 4812360 | S36: 364250 | T36: 1372770 | U36: 1624300 | V36: 867080 | W36: 322220 | X36: 326270 | Y36: 59840 | AD36: =SUM(R36:AC36) -> 9749090 | AE36: =IF(OR(AD36="", P36=""), 0, IFERROR((AD36-P36)/P36, IF(AD36<>0, 1, 0))) -> -0.3806228 | AF36: =IFERROR(_xlfn.RANK.EQ(AD36, $AD$2:$AD$450), "") -> 50
A37: POLO RALPH LAUREN | B37: changzhou richland international trade co.,ltd | C37: 113360 | D37: 398980 | E37: 3371690 | F37: 4357940 | G37: 33080 | H37: 0 | I37: 1584140 | J37: 0 | K37: 0 | L37: 0 | M37: 93680 | N37: 77820 | O37: 0 | P37: =SUM(C37:I37,K37) -> 9859190 | Q37: =SUM(C37:J37,L37:O37) -> 10030690 | R37: 1339230 | S37: 691050 | T37: 1199680 | U37: 2024780 | V37: 633050 | W37: 0 | X37: 0 | Y37: 0 | AD37: =SUM(R37:AC37) -> 5887790 | AE37: =IF(OR(AD37="", P37=""), 0, IFERROR((AD37-P37)/P37, IF(AD37<>0, 1, 0))) -> -0.402812 | AF37: =IFERROR(_xlfn.RANK.EQ(AD37, $AD$2:$AD$450), "") -> 73
A38: POLO RALPH LAUREN | B38: MEN-CHUEN FIBRE INDUSTRY CO.,LTD. | C38: 3216590 | D38: 248030 | E38: 1732910 | F38: 1710640 | G38: 1322530 | H38: 1026520 | I38: 3229670 | J38: 765060 | K38: 765060 | L38: 254870 | M38: 255140 | N38: 1464270 | O38: 5638360 | P38: =SUM(C38:I38,K38) -> 13251950 | Q38: =SUM(C38:J38,L38:O38) -> 20864590 | R38: 1759910 | S38: 262440 | T38: 1396410 | U38: 1521440 | V38: 4172460 | W38: 1242040 | X38: 395700 | Y38: 0 | AD38: =SUM(R38:AC38) -> 10750400 | AE38: =IF(OR(AD38="", P38=""), 0, IFERROR((AD38-P38)/P38, IF(AD38<>0, 1, 0))) -> -0.18876845 | AF38: =IFERROR(_xlfn.RANK.EQ(AD38, $AD$2:$AD$450), "") -> 47
A39: POLO RALPH LAUREN | B39: Huizhou Yide Textile Technology Co.,Ltd | C39: 2067160 | D39: 3783100 | E39: 1298680 | F39: 674160 | G39: 402050 | H39: 1429440 | I39: 2434870 | J39: 1140960 | K39: 1140960 | L39: 178260 | M39: 466110 | N39: 803540 | O39: 0 | P39: =SUM(C39:I39,K39) -> 13230420 | Q39: =SUM(C39:J39,L39:O39) -> 14678330 | R39: 607090 | T39: 337610 | U39: 0 | V39: 0 | W39: 2054080 | X39: 42270 | Y39: 733530 | AD39: =SUM(R39:AC39) -> 3774580 | AE39: =IF(OR(AD39="", P39=""), 0, IFERROR((AD39-P39)/P39, IF(AD39<>0, 1, 0))) -> -0.71470445 | AF39: =IFERROR(_xlfn.RANK.EQ(AD39, $AD$2:$AD$450), "") -> 96
A40: POLO RALPH LAUREN | B40: KEN YUAN KNITTING FACTORY LTD | C40: 918280 | D40: 0 | E40: 1960300 | F40: 2486510 | G40: 2863860 | H40: 54360 | I40: 2996210 | J40: 595710 | K40: 595710 | L40: 1074120 | M40: 571620 | N40: 61550 | O40: 4477380 | P40: =SUM(C40:I40,K40) -> 11875230 | Q40: =SUM(C40:J40,L40:O40) -> 18059900 | S40: 2217220 | T40: 2078600 | U40: 1888230 | V40: 807050 | W40: 484080 | X40: 111250 | Y40: 1111020 | AD40: =SUM(R40:AC40) -> 8697450 | AE40: =IF(OR(AD40="", P40=""), 0, IFERROR((AD40-P40)/P40, IF(AD40<>0, 1, 0))) -> -0.26759734 | AF40: =IFERROR(_xlfn.RANK.EQ(AD40, $AD$2:$AD$450), "") -> 59
...

Sheet global part2
A1: 바이어명 | B1: 업체명 | C1: 25년 1월 | D1: 25년 2월 | E1: 25년 3월 | F1: 25년 4월 | G1: 25년 5월 | H1: 25년 6월 | I1: 25년 7월 | J1: 25년 8월 | K1: 25년 8월 (~25일) | L1: 25년 9월 | M1: 25년 10월 | N1: 25년 11월 | O1: 25년 12월 | P1: 25년 합계 (~8월 25일) | Q1: 25년 합계 | R1: 26년 1월 | S1: 26년 2월 | T1: 26년 3월 | U1: 26년 4월 | V1: 26년 5월 | W1: 26년 6월 | X1: 26년 7월 | Y1: 26년 8월 (~25일) | Z1: 26년 9월 | AA1: 26년 10월 | AB1: 26년 11월 | AC1: 26년 12월 | AD1: 26년 합계 | AE1: 증감율 | AF1: 업체 순위
A2: GUESS | B2: GREENWEAR LIMITED | C2: 451260 | D2: 2359350 | E2: 8945140 | F2: 5270000 | G2: 21723170 | H2: 6476690 | I2: 4077320 | J2: 7254600 | K2: 5885890 | L2: 1997350 | M2: 5524920 | N2: 6373480 | O2: 1959150 | P2: =SUM(C2:I2,K2) -> 55188820 | Q2: =SUM(C2:J2,L2:O2) -> 72412430 | R2: 3177530 | S2: 652220 | T2: 4654580 | U2: 2796200 | V2: 0 | W2: 0 | X2: 0 | Y2: 0 | AD2: =SUM(R2:AC2) -> 11280530 | AE2: =IF(OR(AD2="", P2=""), 0, IFERROR((AD2-P2)/P2, IF(AD2<>0, 1, 0))) -> -0.79560117 | AF2: =IFERROR(_xlfn.RANK.EQ(AD2, $AD$2:$AD$483), "") -> 3
A3: GUESS | B3: SHANGHAI WESTLAN INTERNATIONAL TRADING CO.,LTD | C3: 5601510 | D3: 1790090 | E3: 1771370 | F3: 11102350 | G3: 3877860 | H3: 1434450 | I3: 5285910 | J3: 2880070 | K3: 2529570 | L3: 2320750 | M3: 2630770 | N3: 3219890 | O3: 1963690 | P3: =SUM(C3:I3,K3) -> 33393110 | Q3: =SUM(C3:J3,L3:O3) -> 43878710 | R3: 8076940 | S3: 2652730 | T3: 4256640 | U3: 11776440 | V3: 4106570 | W3: 593970 | X3: 0 | Y3: 0 | AD3: =SUM(R3:AC3) -> 31463290 | AE3: =IF(OR(AD3="", P3=""), 0, IFERROR((AD3-P3)/P3, IF(AD3<>0, 1, 0))) -> -0.057790963 | AF3: =IFERROR(_xlfn.RANK.EQ(AD3, $AD$2:$AD$483), "") -> 1
A4: GUESS | B4: TONGXIANG EASUN FOREIGN TRADE CO.,LTD | C4: 5851630 | D4: 328200 | E4: 2973230 | F4: 10588750 | G4: 1767940 | H4: 859070 | I4: 5139600 | J4: 2186300 | K4: 2010190 | L4: 545660 | M4: 3408000 | N4: 699720 | O4: 3092050 | P4: =SUM(C4:I4,K4) -> 29518610 | Q4: =SUM(C4:J4,L4:O4) -> 37440150 | R4: 4804850 | S4: 156890 | T4: 2635530 | U4: 2789070 | V4: 0 | W4: 0 | X4: 0 | Y4: 0 | AD4: =SUM(R4:AC4) -> 10386340 | AE4: =IF(OR(AD4="", P4=""), 0, IFERROR((AD4-P4)/P4, IF(AD4<>0, 1, 0))) -> -0.64814265 | AF4: =IFERROR(_xlfn.RANK.EQ(AD4, $AD$2:$AD$483), "") -> 4 | AH4: 행 레이블 | AI4: 합계 : 25년 합계 | AJ4: 합계 : 26년 합계 | AK4: 증감수수료 | AL4: 증감율
A5: GUESS | B5: HRJ Fashion & Accessories Corp. Ltd. | C5: 873940 | D5: 0 | E5: 2986110 | F5: 2550470 | G5: 27880 | H5: 0 | I5: 0 | J5: 0 | K5: 0 | L5: 0 | M5: 0 | N5: 0 | O5: 0 | P5: =SUM(C5:I5,K5) -> 6438400 | Q5: =SUM(C5:J5,L5:O5) -> 6438400 | AD5: =SUM(R5:AC5) -> 0 | AE5: =IF(OR(AD5="", P5=""), 0, IFERROR((AD5-P5)/P5, IF(AD5<>0, 1, 0))) -> -1 | AF5: =IFERROR(_xlfn.RANK.EQ(AD5, $AD$2:$AD$483), "") -> 189 | AH5: GUESS | AI5: 172545210 | AJ5: 78015170 | AK5: =AJ5-AI5 -> -94530040 | AL5: =IFERROR((AJ5-AI5)/AI5, 0) -> -0.54785665
A6: GUESS | B6: Joy fashion co.,ltd. | D6: 107370 | E6: 1630480 | F6: 2106670 | G6: 1696980 | H6: 287050 | I6: 486150 | J6: 894740 | K6: 223390 | L6: 728340 | M6: 505270 | N6: 967010 | O6: 312360 | P6: =SUM(C6:I6,K6) -> 6538090 | Q6: =SUM(C6:J6,L6:O6) -> 9722420 | R6: 807940 | S6: 217710 | T6: 1827660 | U6: 2007630 | V6: 0 | W6: 0 | X6: 0 | Y6: 0 | AD6: =SUM(R6:AC6) -> 4860940 | AE6: =IF(OR(AD6="", P6=""), 0, IFERROR((AD6-P6)/P6, IF(AD6<>0, 1, 0))) -> -0.25651987 | AF6: =IFERROR(_xlfn.RANK.EQ(AD6, $AD$2:$AD$483), "") -> 17 | AH6: COLOSSEUM | AI6: 37955070 | AJ6: 68042000 | AK6: =AJ6-AI6 -> 30086930 | AL6: =IFERROR((AJ6-AI6)/AI6, 0) -> 0.79269858
A7: GUESS | B7: Jiaxing Buford Trading Co.,Ltd | C7: 595240 | D7: 60880 | E7: 1309160 | F7: 1505400 | G7: 692430 | H7: 0 | I7: 1629660 | J7: 30890 | K7: 30890 | L7: 0 | M7: 586880 | N7: 1067780 | O7: 107900 | P7: =SUM(C7:I7,K7) -> 5823660 | Q7: =SUM(C7:J7,L7:O7) -> 7586220 | R7: 1287200 | S7: 987160 | T7: 0 | U7: 0 | V7: 0 | W7: 0 | X7: 0 | Y7: 0 | AD7: =SUM(R7:AC7) -> 2274360 | AE7: =IF(OR(AD7="", P7=""), 0, IFERROR((AD7-P7)/P7, IF(AD7<>0, 1, 0))) -> -0.60946209 | AF7: =IFERROR(_xlfn.RANK.EQ(AD7, $AD$2:$AD$483), "") -> 29 | AH7: 기타(AATCC) | AI7: 34469970 | AJ7: 43366350 | AK7: =AJ7-AI7 -> 8896380 | AL7: =IFERROR((AJ7-AI7)/AI7, 0) -> 0.25809074
A8: GUESS | B8: Kunshan Huayue Textile&Garment Co.Ltd | C8: 608350 | D8: 0 | E8: 1404700 | F8: 1116040 | G8: 0 | H8: 0 | I8: 713500 | J8: 204290 | K8: 162560 | L8: 365530 | M8: 39790 | N8: 0 | O8: 0 | P8: =SUM(C8:I8,K8) -> 4005150 | Q8: =SUM(C8:J8,L8:O8) -> 4452200 | AD8: =SUM(R8:AC8) -> 0 | AE8: =IF(OR(AD8="", P8=""), 0, IFERROR((AD8-P8)/P8, IF(AD8<>0, 1, 0))) -> -1 | AF8: =IFERROR(_xlfn.RANK.EQ(AD8, $AD$2:$AD$483), "") -> 189 | AH8: FASHION NOVA | AI8: 19700080 | AJ8: 35686360 | AK8: =AJ8-AI8 -> 15986280 | AL8: =IFERROR((AJ8-AI8)/AI8, 0) -> 0.811483
A9: GUESS | B9: SHAOXING DARIN TEXTILE CO., LTD | C9: 1070390 | D9: 1133870 | E9: 70710 | F9: 0 | G9: 0 | H9: 678450 | I9: 0 | J9: 30280 | K9: 30280 | L9: 1037130 | M9: 678440 | N9: 0 | O9: 0 | P9: =SUM(C9:I9,K9) -> 2983700 | Q9: =SUM(C9:J9,L9:O9) -> 4699270 | R9: 517730 | T9: 30160 | U9: 0 | V9: 0 | W9: 0 | X9: 0 | Y9: 0 | AD9: =SUM(R9:AC9) -> 547890 | AE9: =IF(OR(AD9="", P9=""), 0, IFERROR((AD9-P9)/P9, IF(AD9<>0, 1, 0))) -> -0.81637229 | AF9: =IFERROR(_xlfn.RANK.EQ(AD9, $AD$2:$AD$483), "") -> 85 | AH9: ACTIVE USA, INC. | AI9: 16536800 | AJ9: 21607630 | AK9: =AJ9-AI9 -> 5070830 | AL9: =IFERROR((AJ9-AI9)/AI9, 0) -> 0.30663913
A10: GUESS | B10: Changzhou ShengLai garments co.,ltd. | C10: 87480 | D10: 516760 | E10: 662750 | F10: 69290 | G10: 861070 | H10: 250330 | I10: 332570 | J10: 27980 | K10: 27980 | L10: 0 | M10: 491080 | N10: 0 | O10: 125250 | P10: =SUM(C10:I10,K10) -> 2808230 | Q10: =SUM(C10:J10,L10:O10) -> 3424560 | S10: 143650 | T10: 704190 | U10: 0 | V10: 0 | W10: 0 | X10: 0 | Y10: 0 | AD10: =SUM(R10:AC10) -> 847840 | AE10: =IF(OR(AD10="", P10=""), 0, IFERROR((AD10-P10)/P10, IF(AD10<>0, 1, 0))) -> -0.69808741 | AF10: =IFERROR(_xlfn.RANK.EQ(AD10, $AD$2:$AD$483), "") -> 63 | AH10: Byer California | AI10: 5779910 | AJ10: 12597370 | AK10: =AJ10-AI10 -> 6817460 | AL10: =IFERROR((AJ10-AI10)/AI10, 0) -> 1.1795097
A11: GUESS | B11: NINGBO LONGFEI IMP&EXP CO.LTD | C11: 116530 | D11: 0 | E11: 208630 | F11: 1183160 | G11: 556700 | H11: 191610 | I11: 603360 | J11: 495020 | K11: 307420 | L11: 180390 | M11: 298560 | N11: 208040 | O11: 28840 | P11: =SUM(C11:I11,K11) -> 3167410 | Q11: =SUM(C11:J11,L11:O11) -> 4070840 | R11: 171060 | S11: 218490 | T11: 329420 | U11: 335020 | V11: 0 | W11: 0 | X11: 0 | Y11: 0 | AD11: =SUM(R11:AC11) -> 1053990 | AE11: =IF(OR(AD11="", P11=""), 0, IFERROR((AD11-P11)/P11, IF(AD11<>0, 1, 0))) -> -0.66723916 | AF11: =IFERROR(_xlfn.RANK.EQ(AD11, $AD$2:$AD$483), "") -> 52 | AH11: KAN CAN USA Inc. | AI11: 2167800 | AJ11: 8544360 | AK11: =AJ11-AI11 -> 6376560 | AL11: =IFERROR((AJ11-AI11)/AI11, 0) -> 2.9414891
A12: GUESS | B12: shaoxing yongyao textile co.,ltd | C12: 109520 | D12: 452130 | E12: 274570 | F12: 598720 | G12: 593120 | H12: 141630 | I12: 650410 | J12: 349030 | K12: 349030 | L12: 0 | M12: 360930 | N12: 0 | O12: 3610690 | P12: =SUM(C12:I12,K12) -> 3169130 | Q12: =SUM(C12:J12,L12:O12) -> 7140750 | R12: 1076010 | S12: 549080 | T12: 624470 | U12: 0 | V12: 0 | W12: 0 | X12: 0 | Y12: 0 | AD12: =SUM(R12:AC12) -> 2249560 | AE12: =IF(OR(AD12="", P12=""), 0, IFERROR((AD12-P12)/P12, IF(AD12<>0, 1, 0))) -> -0.29016481 | AF12: =IFERROR(_xlfn.RANK.EQ(AD12, $AD$2:$AD$483), "") -> 30 | AH12: NEWELL | AI12: 9940140 | AJ12: 7445780 | AK12: =AJ12-AI12 -> -2494360 | AL12: =IFERROR((AJ12-AI12)/AI12, 0) -> -0.25093812
A13: GUESS | B13: SHAOXING EXCELLENT TEXTILE CO.LTD | C13: 678790 | D13: 0 | E13: 111890 | F13: 732610 | G13: 0 | H13: 530040 | I13: 504220 | J13: 0 | K13: 0 | L13: 0 | M13: 0 | N13: 0 | O13: 171310 | P13: =SUM(C13:I13,K13) -> 2557550 | Q13: =SUM(C13:J13,L13:O13) -> 2728860 | R13: 333980 | T13: 0 | U13: 392640 | V13: 0 | W13: 0 | X13: 0 | Y13: 0 | AD13: =SUM(R13:AC13) -> 726620 | AE13: =IF(OR(AD13="", P13=""), 0, IFERROR((AD13-P13)/P13, IF(AD13<>0, 1, 0))) -> -0.71589216 | AF13: =IFERROR(_xlfn.RANK.EQ(AD13, $AD$2:$AD$483), "") -> 71 | AH13: 기타(ISO) | AI13: 10384920 | AJ13: 6201190 | AK13: =AJ13-AI13 -> -4183730 | AL13: =IFERROR((AJ13-AI13)/AI13, 0) -> -0.40286589
A14: GUESS | B14: Indochine International Ltd | C14: 535910 | D14: 285090 | E14: 68520 | F14: 561940 | G14: 27560 | H14: 467010 | I14: 389450 | J14: 522140 | K14: 385730 | L14: 1041340 | M14: 598320 | N14: 312840 | O14: 982540 | P14: =SUM(C14:I14,K14) -> 2721210 | Q14: =SUM(C14:J14,L14:O14) -> 5792660 | R14: 1620080 | S14: 1190930 | T14: 66420 | U14: 0 | V14: 0 | W14: 0 | X14: 0 | Y14: 0 | AD14: =SUM(R14:AC14) -> 2877430 | AE14: =IF(OR(AD14="", P14=""), 0, IFERROR((AD14-P14)/P14, IF(AD14<>0, 1, 0))) -> 0.057408285 | AF14: =IFERROR(_xlfn.RANK.EQ(AD14, $AD$2:$AD$483), "") -> 26 | AH14: BUCKLE | AI14: 1418830 | AJ14: 2132590 | AK14: =AJ14-AI14 -> 713760 | AL14: =IFERROR((AJ14-AI14)/AI14, 0) -> 0.50306238
A15: GUESS | B15: JIN HONG INTERNATIONAL TRADING(SHANGHAI) CO.LTD | C15: 273600 | D15: 0 | E15: 802560 | F15: 38800 | G15: 0 | H15: 0 | I15: 0 | J15: 0 | K15: 0 | L15: 32780 | M15: 365420 | N15: 58150 | O15: 0 | P15: =SUM(C15:I15,K15) -> 1114960 | Q15: =SUM(C15:J15,L15:O15) -> 1571310 | R15: 28970 | S15: 87630 | T15: 210970 | U15: 850270 | V15: 0 | W15: 0 | X15: 0 | Y15: 0 | AD15: =SUM(R15:AC15) -> 1177840 | AE15: =IF(OR(AD15="", P15=""), 0, IFERROR((AD15-P15)/P15, IF(AD15<>0, 1, 0))) -> 0.056396642 | AF15: =IFERROR(_xlfn.RANK.EQ(AD15, $AD$2:$AD$483), "") -> 49 | AH15: TEMU | AI15: 1729130 | AJ15: 32220 | AK15: =AJ15-AI15 -> -1696910 | AL15: =IFERROR((AJ15-AI15)/AI15, 0) -> -0.98136635
A16: GUESS | B16: Suzhou D&C Manufacture Group | D16: 0 | E16: 460760 | F16: 428180 | G16: 210610 | H16: 27270 | I16: 355370 | J16: 0 | K16: 0 | L16: 57970 | M16: 0 | N16: 0 | O16: 684350 | P16: =SUM(C16:I16,K16) -> 1482190 | Q16: =SUM(C16:J16,L16:O16) -> 2224510 | R16: 460610 | T16: 469800 | U16: 0 | V16: 0 | W16: 0 | X16: 0 | Y16: 0 | AD16: =SUM(R16:AC16) -> 930410 | AE16: =IF(OR(AD16="", P16=""), 0, IFERROR((AD16-P16)/P16, IF(AD16<>0, 1, 0))) -> -0.37227346 | AF16: =IFERROR(_xlfn.RANK.EQ(AD16, $AD$2:$AD$483), "") -> 58 | AH16: F21 OpCo, LLC | AI16: 47027820 | AJ16: 0 | AK16: =AJ16-AI16 -> -47027820 | AL16: =IFERROR((AJ16-AI16)/AI16, 0) -> -1
A17: GUESS | B17: HUALEY KNITWEARS LTD. | C17: 105890 | D17: 283470 | E17: 0 | F17: 85350 | G17: 485150 | H17: 0 | I17: 92950 | J17: 445990 | K17: 390350 | L17: 0 | M17: 260630 | N17: 387530 | O17: 0 | P17: =SUM(C17:I17,K17) -> 1443160 | Q17: =SUM(C17:J17,L17:O17) -> 2146960 | R17: 756520 | S17: 28860 | T17: 0 | U17: 0 | V17: 0 | W17: 0 | X17: 0 | Y17: 0 | AD17: =SUM(R17:AC17) -> 785380 | AE17: =IF(OR(AD17="", P17=""), 0, IFERROR((AD17-P17)/P17, IF(AD17<>0, 1, 0))) -> -0.45579146 | AF17: =IFERROR(_xlfn.RANK.EQ(AD17, $AD$2:$AD$483), "") -> 67 | AH17: MARMOT | AI17: 281050 | AJ17: 0 | AK17: =AJ17-AI17 -> -281050 | AL17: =IFERROR((AJ17-AI17)/AI17, 0) -> -1
A18: GUESS | B18: C.H.A DESIGN EXPORT (H.Z) LTD | C18: 976170 | D18: 0 | E18: 0 | F18: 0 | G18: 0 | H18: 0 | I18: 0 | J18: 0 | K18: 0 | L18: 0 | M18: 0 | N18: 0 | O18: 0 | P18: =SUM(C18:I18,K18) -> 976170 | Q18: =SUM(C18:J18,L18:O18) -> 976170 | AD18: =SUM(R18:AC18) -> 0 | AE18: =IF(OR(AD18="", P18=""), 0, IFERROR((AD18-P18)/P18, IF(AD18<>0, 1, 0))) -> -1 | AF18: =IFERROR(_xlfn.RANK.EQ(AD18, $AD$2:$AD$483), "") -> 189 | AH18: Kasper (구.JONES APPAREL GROUP) | AI18: 0 | AJ18: 0 | AK18: =AJ18-AI18 -> 0 | AL18: =IFERROR((AJ18-AI18)/AI18, 0) -> 0
A19: GUESS | B19: JULIA | D19: 0 | E19: 384970 | F19: 28600 | G19: 330790 | H19: 551280 | I19: 0 | J19: 0 | K19: 0 | L19: 27870 | M19: 0 | N19: 0 | O19: 0 | P19: =SUM(C19:I19,K19) -> 1295640 | Q19: =SUM(C19:J19,L19:O19) -> 1323510 | AD19: =SUM(R19:AC19) -> 0 | AE19: =IF(OR(AD19="", P19=""), 0, IFERROR((AD19-P19)/P19, IF(AD19<>0, 1, 0))) -> -1 | AF19: =IFERROR(_xlfn.RANK.EQ(AD19, $AD$2:$AD$483), "") -> 189 | AH19: Icer Brands | AI19: 0 | AJ19: 0 | AK19: =AJ19-AI19 -> 0 | AL19: =IFERROR((AJ19-AI19)/AI19, 0) -> 0
A20: GUESS | B20: ZHEJIANG JIAYE P&D CO.,LTD | D20: 130100 | E20: 0 | F20: 606260 | G20: 0 | H20: 0 | I20: 194630 | J20: 298480 | K20: 298480 | L20: 616780 | M20: 206880 | N20: 0 | O20: 0 | P20: =SUM(C20:I20,K20) -> 1229470 | Q20: =SUM(C20:J20,L20:O20) -> 2053130 | R20: 283440 | S20: 162830 | T20: 0 | U20: 156570 | V20: 0 | W20: 0 | X20: 0 | Y20: 0 | AD20: =SUM(R20:AC20) -> 602840 | AE20: =IF(OR(AD20="", P20=""), 0, IFERROR((AD20-P20)/P20, IF(AD20<>0, 1, 0))) -> -0.5096749 | AF20: =IFERROR(_xlfn.RANK.EQ(AD20, $AD$2:$AD$483), "") -> 82 | AH20: 총합계 | AI20: 359936730 | AJ20: 283671020 | AK20: =AJ20-AI20 -> -76265710 | AL20: =IFERROR((AJ20-AI20)/AI20, 0) -> -0.21188643
A21: GUESS | B21: Shaoxing Metop Textile Technology Co.,Ltd | D21: 0 | E21: 0 | F21: 480060 | G21: 172810 | H21: 110800 | I21: 1082930 | J21: 95540 | K21: 109410 | L21: 684390 | M21: 181890 | N21: 136970 | O21: 239100 | P21: =SUM(C21:I21,K21) -> 1956010 | Q21: =SUM(C21:J21,L21:O21) -> 3184490 | R21: 261000 | S21: 29280 | T21: 338260 | U21: 787200 | V21: 0 | W21: 0 | X21: 0 | Y21: 0 | AD21: =SUM(R21:AC21) -> 1415740 | AE21: =IF(OR(AD21="", P21=""), 0, IFERROR((AD21-P21)/P21, IF(AD21<>0, 1, 0))) -> -0.27621024 | AF21: =IFERROR(_xlfn.RANK.EQ(AD21, $AD$2:$AD$483), "") -> 45
A22: GUESS | B22: JIANGSU FENGYIN TEXTILE INDUSTRIAL CO LTD | D22: 0 | E22: 140780 | F22: 276180 | G22: 206410 | H22: 0 | I22: 0 | J22: 0 | K22: 0 | L22: 0 | M22: 0 | N22: 0 | O22: 0 | P22: =SUM(C22:I22,K22) -> 623370 | Q22: =SUM(C22:J22,L22:O22) -> 623370 | AD22: =SUM(R22:AC22) -> 0 | AE22: =IF(OR(AD22="", P22=""), 0, IFERROR((AD22-P22)/P22, IF(AD22<>0, 1, 0))) -> -1 | AF22: =IFERROR(_xlfn.RANK.EQ(AD22, $AD$2:$AD$483), "") -> 189
A23: GUESS | B23: ARCH TEXTILES MANUFACTURE CORP | D23: 0 | E23: 48770 | F23: 231860 | G23: 317030 | H23: 0 | I23: 0 | J23: 0 | K23: 0 | L23: 0 | M23: 0 | N23: 0 | O23: 0 | P23: =SUM(C23:I23,K23) -> 597660 | Q23: =SUM(C23:J23,L23:O23) -> 597660 | AD23: =SUM(R23:AC23) -> 0 | AE23: =IF(OR(AD23="", P23=""), 0, IFERROR((AD23-P23)/P23, IF(AD23<>0, 1, 0))) -> -1 | AF23: =IFERROR(_xlfn.RANK.EQ(AD23, $AD$2:$AD$483), "") -> 189
A24: GUESS | B24: JECA LIMITED | D24: 0 | E24: 0 | F24: 222520 | G24: 0 | H24: 174180 | I24: 0 | J24: 0 | K24: 0 | L24: 320500 | M24: 0 | N24: 87320 | O24: 0 | P24: =SUM(C24:I24,K24) -> 396700 | Q24: =SUM(C24:J24,L24:O24) -> 804520 | AD24: =SUM(R24:AC24) -> 0 | AE24: =IF(OR(AD24="", P24=""), 0, IFERROR((AD24-P24)/P24, IF(AD24<>0, 1, 0))) -> -1 | AF24: =IFERROR(_xlfn.RANK.EQ(AD24, $AD$2:$AD$483), "") -> 189
A25: GUESS | B25: CIXI HAITENG PLUSH PRODUCT CO.,LTD | D25: 0 | E25: 0 | F25: 166120 | G25: 28110 | H25: 0 | I25: 0 | J25: 0 | K25: 0 | L25: 0 | M25: 0 | N25: 0 | O25: 0 | P25: =SUM(C25:I25,K25) -> 194230 | Q25: =SUM(C25:J25,L25:O25) -> 194230 | AD25: =SUM(R25:AC25) -> 0 | AE25: =IF(OR(AD25="", P25=""), 0, IFERROR((AD25-P25)/P25, IF(AD25<>0, 1, 0))) -> -1 | AF25: =IFERROR(_xlfn.RANK.EQ(AD25, $AD$2:$AD$483), "") -> 189
A26: GUESS | B26: Teebur Textile(Shanghai)Co.Ltd | D26: 29010 | E26: 0 | F26: 114900 | G26: 43250 | H26: 329890 | I26: 626310 | J26: 27980 | K26: 27980 | L26: 175110 | M26: 47120 | N26: 0 | O26: 199870 | P26: =SUM(C26:I26,K26) -> 1171340 | Q26: =SUM(C26:J26,L26:O26) -> 1593440 | R26: 46570 | T26: 302270 | U26: 0 | V26: 0 | W26: 0 | X26: 0 | Y26: 0 | AD26: =SUM(R26:AC26) -> 348840 | AE26: =IF(OR(AD26="", P26=""), 0, IFERROR((AD26-P26)/P26, IF(AD26<>0, 1, 0))) -> -0.70218724 | AF26: =IFERROR(_xlfn.RANK.EQ(AD26, $AD$2:$AD$483), "") -> 109
A27: GUESS | B27: jiangsu vango fashion co.,ltd | C27: 136310 | D27: 0 | E27: 0 | F27: 0 | G27: 33800 | H27: 0 | I27: 0 | J27: 0 | K27: 0 | L27: 0 | M27: 37980 | N27: 194740 | O27: 0 | P27: =SUM(C27:I27,K27) -> 170110 | Q27: =SUM(C27:J27,L27:O27) -> 402830 | R27: 425820 | T27: 0 | U27: 97880 | V27: 0 | W27: 0 | X27: 0 | Y27: 0 | AD27: =SUM(R27:AC27) -> 523700 | AE27: =IF(OR(AD27="", P27=""), 0, IFERROR((AD27-P27)/P27, IF(AD27<>0, 1, 0))) -> 2.0785962 | AF27: =IFERROR(_xlfn.RANK.EQ(AD27, $AD$2:$AD$483), "") -> 89
A28: GUESS | B28: NANTONG ZHONGDA TEXTILE CO.LTD | D28: 0 | E28: 0 | F28: 150070 | G28: 0 | H28: 0 | I28: 148580 | J28: 0 | K28: 0 | L28: 0 | M28: 287150 | N28: 158830 | O28: 0 | P28: =SUM(C28:I28,K28) -> 298650 | Q28: =SUM(C28:J28,L28:O28) -> 744630 | R28: 29340 | S28: 277850 | T28: 1095350 | U28: 0 | V28: 0 | W28: 0 | X28: 0 | Y28: 0 | AD28: =SUM(R28:AC28) -> 1402540 | AE28: =IF(OR(AD28="", P28=""), 0, IFERROR((AD28-P28)/P28, IF(AD28<>0, 1, 0))) -> 3.6962665 | AF28: =IFERROR(_xlfn.RANK.EQ(AD28, $AD$2:$AD$483), "") -> 46
A29: GUESS | B29: ZHEJIANG CHARMING DYEING AND FINISHING CO.,LTD | D29: 0 | E29: 29180 | F29: 60270 | G29: 0 | H29: 0 | I29: 0 | J29: 149020 | K29: 149020 | L29: 42910 | M29: 0 | N29: 0 | O29: 44920 | P29: =SUM(C29:I29,K29) -> 238470 | Q29: =SUM(C29:J29,L29:O29) -> 326300 | T29: 30160 | U29: 0 | V29: 0 | W29: 0 | X29: 0 | Y29: 0 | AD29: =SUM(R29:AC29) -> 30160 | AE29: =IF(OR(AD29="", P29=""), 0, IFERROR((AD29-P29)/P29, IF(AD29<>0, 1, 0))) -> -0.87352707 | AF29: =IFERROR(_xlfn.RANK.EQ(AD29, $AD$2:$AD$483), "") -> 180
A30: GUESS | B30: GOOD RICH TEXTILE LIMITED | C30: 58570 | D30: 0 | E30: 0 | F30: 0 | G30: 0 | H30: 0 | I30: 0 | J30: 544100 | K30: 544100 | L30: 0 | M30: 0 | N30: 0 | O30: 167960 | P30: =SUM(C30:I30,K30) -> 602670 | Q30: =SUM(C30:J30,L30:O30) -> 770630 | R30: 286380 | U30: 0 | V30: 0 | W30: 0 | X30: 0 | Y30: 0 | AD30: =SUM(R30:AC30) -> 286380 | AE30: =IF(OR(AD30="", P30=""), 0, IFERROR((AD30-P30)/P30, IF(AD30<>0, 1, 0))) -> -0.52481458 | AF30: =IFERROR(_xlfn.RANK.EQ(AD30, $AD$2:$AD$483), "") -> 119
A31: GUESS | B31: ZHEJIANG XUSHENG TEXTILE CO., LTD | D31: 0 | E31: 48150 | F31: 0 | G31: 0 | H31: 0 | I31: 0 | J31: 0 | K31: 0 | L31: 0 | M31: 0 | N31: 0 | O31: 0 | P31: =SUM(C31:I31,K31) -> 48150 | Q31: =SUM(C31:J31,L31:O31) -> 48150 | AD31: =SUM(R31:AC31) -> 0 | AE31: =IF(OR(AD31="", P31=""), 0, IFERROR((AD31-P31)/P31, IF(AD31<>0, 1, 0))) -> -1 | AF31: =IFERROR(_xlfn.RANK.EQ(AD31, $AD$2:$AD$483), "") -> 189
A32: GUESS | B32: HIGH FASHION(CHINA) CO.,LTD | P32: =SUM(C32:I32,K32) -> 0 | Q32: =SUM(C32:J32,L32:O32) -> 0 | AD32: =SUM(R32:AC32) -> 0 | AE32: =IF(OR(AD32="", P32=""), 0, IFERROR((AD32-P32)/P32, IF(AD32<>0, 1, 0))) -> 0 | AF32: =IFERROR(_xlfn.RANK.EQ(AD32, $AD$2:$AD$483), "") -> 189
A33: GUESS | B33: LABELTEX(SHANGHAI) CO.,LTD | P33: =SUM(C33:I33,K33) -> 0 | Q33: =SUM(C33:J33,L33:O33) -> 0 | AD33: =SUM(R33:AC33) -> 0 | AE33: =IF(OR(AD33="", P33=""), 0, IFERROR((AD33-P33)/P33, IF(AD33<>0, 1, 0))) -> 0 | AF33: =IFERROR(_xlfn.RANK.EQ(AD33, $AD$2:$AD$483), "") -> 189
A34: GUESS | B34: SUZHOU COBEST TEXTILES CO.,LTD | D34: 0 | E34: 0 | F34: 0 | G34: 0 | H34: 0 | I34: 178360 | J34: 0 | K34: 0 | L34: 482150 | M34: 189240 | N34: 0 | O34: 362530 | P34: =SUM(C34:I34,K34) -> 178360 | Q34: =SUM(C34:J34,L34:O34) -> 1212280 | U34: 619540 | V34: 0 | W34: 0 | X34: 0 | Y34: 0 | AD34: =SUM(R34:AC34) -> 619540 | AE34: =IF(OR(AD34="", P34=""), 0, IFERROR((AD34-P34)/P34, IF(AD34<>0, 1, 0))) -> 2.4735367 | AF34: =IFERROR(_xlfn.RANK.EQ(AD34, $AD$2:$AD$483), "") -> 81
A35: GUESS | B35: GUANGZHOU MEIYINGDA TEXTILE CO.LTD | D35: 0 | E35: 0 | F35: 0 | G35: 0 | H35: 27330 | I35: 0 | J35: 0 | K35: 0 | L35: 0 | M35: 0 | N35: 0 | O35: 0 | P35: =SUM(C35:I35,K35) -> 27330 | Q35: =SUM(C35:J35,L35:O35) -> 27330 | AD35: =SUM(R35:AC35) -> 0 | AE35: =IF(OR(AD35="", P35=""), 0, IFERROR((AD35-P35)/P35, IF(AD35<>0, 1, 0))) -> -1 | AF35: =IFERROR(_xlfn.RANK.EQ(AD35, $AD$2:$AD$483), "") -> 189
A36: GUESS | B36: Changzhou Mengda Textile Co., Ltd. | D36: 0 | E36: 0 | F36: 0 | G36: 0 | H36: 0 | I36: 0 | J36: 0 | L36: 803980 | M36: 0 | N36: 0 | O36: 0 | P36: =SUM(C36:I36,K36) -> 0 | Q36: =SUM(C36:J36,L36:O36) -> 803980 | T36: 29290 | U36: 196980 | V36: 0 | W36: 0 | X36: 0 | Y36: 0 | AD36: =SUM(R36:AC36) -> 226270 | AE36: =IF(OR(AD36="", P36=""), 0, IFERROR((AD36-P36)/P36, IF(AD36<>0, 1, 0))) -> 1 | AF36: =IFERROR(_xlfn.RANK.EQ(AD36, $AD$2:$AD$483), "") -> 127
A37: GUESS | B37: BRIGHTEX SHANGHAI LIMITED | P37: =SUM(C37:I37,K37) -> 0 | Q37: =SUM(C37:J37,L37:O37) -> 0 | AD37: =SUM(R37:AC37) -> 0 | AE37: =IF(OR(AD37="", P37=""), 0, IFERROR((AD37-P37)/P37, IF(AD37<>0, 1, 0))) -> 0 | AF37: =IFERROR(_xlfn.RANK.EQ(AD37, $AD$2:$AD$483), "") -> 189
A38: GUESS | B38: Shanghai Haomaier Clothing &Textile Co.Ltd | P38: =SUM(C38:I38,K38) -> 0 | Q38: =SUM(C38:J38,L38:O38) -> 0 | AD38: =SUM(R38:AC38) -> 0 | AE38: =IF(OR(AD38="", P38=""), 0, IFERROR((AD38-P38)/P38, IF(AD38<>0, 1, 0))) -> 0 | AF38: =IFERROR(_xlfn.RANK.EQ(AD38, $AD$2:$AD$483), "") -> 189
A39: GUESS | B39: SHAOXING KEQIAO SPLEND TEXTILE CO., LTD | P39: =SUM(C39:I39,K39) -> 0 | Q39: =SUM(C39:J39,L39:O39) -> 0 | AD39: =SUM(R39:AC39) -> 0 | AE39: =IF(OR(AD39="", P39=""), 0, IFERROR((AD39-P39)/P39, IF(AD39<>0, 1, 0))) -> 0 | AF39: =IFERROR(_xlfn.RANK.EQ(AD39, $AD$2:$AD$483), "") -> 189
A40: GUESS | B40: PingHu Top Circle Knitting Co.,Ltd | P40: =SUM(C40:I40,K40) -> 0 | Q40: =SUM(C40:J40,L40:O40) -> 0 | AD40: =SUM(R40:AC40) -> 0 | AE40: =IF(OR(AD40="", P40=""), 0, IFERROR((AD40-P40)/P40, IF(AD40<>0, 1, 0))) -> 0 | AF40: =IFERROR(_xlfn.RANK.EQ(AD40, $AD$2:$AD$483), "") -> 189
...

Sheet KC part
A1: 바이어명 | B1: 업체명 | C1: 25년 1월 | D1: 25년 2월 | E1: 25년 3월 | F1: 25년 4월 | G1: 25년 5월 | H1: 25년 6월 | I1: 25년 7월 | J1: 25년 8월 | K1: 25년 8월 (~25일) | L1: 25년 9월 | M1: 25년 10월 | N1: 25년 11월 | O1: 25년 12월 | P1: 25년 합계 (~8월 25일) | Q1: 25년 합계 | R1: 26년 1월 | S1: 26년 2월 | T1: 26년 3월 | U1: 26년 4월 | V1: 26년 5월 | W1: 26년 6월 | X1: 26년 7월 | Y1: 26년 8월 (~25일) | Z1: 26년 9월 | AA1: 26년 10월 | AB1: 26년 11월 | AC1: 26년 12월 | AD1: 26년 합계 | AE1: 증감율 | AF1: 업체 순위
A2: (주)이랜드 | B2: NANTONG FOREMOST HEADWEARS CO.,LTD | C2: 1196750 | D2: 11577150 | E2: 6954250 | F2: 1072500 | G2: 1353600 | H2: 8845150 | I2: 9541150 | J2: 4400450 | K2: 3855950 | L2: 968000 | M2: 2029100 | N2: 2873500 | O2: 9458000 | P2: =SUM(C2:I2,K2) -> 44396500 | Q2: =SUM(C2:J2,L2:O2) -> 60269600 | R2: 13572400 | S2: 5529400 | T2: 2603300 | U2: 1853700 | V2: 900400 | W2: 8343700 | X2: 3433400 | Y2: 5585700 | AD2: =SUM(R2:AC2) -> 41822000 | AE2: =IF(OR(AD2="", P2=""), 0, IFERROR((AD2-P2)/P2, IF(AD2<>0, 1, 0))) -> -0.057988805 | AF2: =IFERROR(_xlfn.RANK.EQ(AD2, $AD$2:$AD$2064), "") -> 3 | AH2: 행 레이블 | AI2: 합계 : 25년 합계 | AJ2: 합계 : 26년 합계 | AK2: 증감수수료 | AL2: 증감율
A3: (주)이랜드 | B3: ANNA | C3: 2754050 | D3: 1239000 | E3: 3167700 | F3: 6051500 | G3: 3674000 | H3: 4060000 | I3: 5826000 | J3: 1937000 | K3: 1536800 | L3: 2969900 | M3: 4106800 | N3: 5160100 | O3: 9135000 | P3: =SUM(C3:I3,K3) -> 28309050 | Q3: =SUM(C3:J3,L3:O3) -> 50081050 | R3: 7283950 | S3: 3948250 | T3: 7697400 | U3: 5603650 | V3: 1462900 | W3: 3889100 | X3: 8150200 | Y3: 9796500 | AD3: =SUM(R3:AC3) -> 47831950 | AE3: =IF(OR(AD3="", P3=""), 0, IFERROR((AD3-P3)/P3, IF(AD3<>0, 1, 0))) -> 0.68963459 | AF3: =IFERROR(_xlfn.RANK.EQ(AD3, $AD$2:$AD$2064), "") -> 2 | AH3: (주)이랜드 | AI3: 782813390 | AJ3: 679112630 | AK3: =AJ3-AI3 -> -103700760 | AL3: =IFERROR((AJ3-AI3)/AI3, 0) -> -0.13247188
A4: (주)이랜드 | B4: 훙레이 | C4: 2818000 | D4: 1185000 | E4: 3698250 | F4: 5009500 | G4: 1053450 | H4: 1715450 | I4: 2603000 | J4: 2628800 | K4: 2002350 | L4: 610400 | M4: 2139750 | N4: 2515800 | O4: 4697700 | P4: =SUM(C4:I4,K4) -> 20085000 | Q4: =SUM(C4:J4,L4:O4) -> 30675100 | R4: 6455400 | S4: 905000 | T4: 4673000 | U4: 4943600 | V4: 2827850 | W4: 1447450 | X4: 2645950 | Y4: 1883400 | AD4: =SUM(R4:AC4) -> 25781650 | AE4: =IF(OR(AD4="", P4=""), 0, IFERROR((AD4-P4)/P4, IF(AD4<>0, 1, 0))) -> 0.28362708 | AF4: =IFERROR(_xlfn.RANK.EQ(AD4, $AD$2:$AD$2064), "") -> 11 | AH4: - | AI4: 238616440 | AJ4: 315838070 | AK4: =AJ4-AI4 -> 77221630 | AL4: =IFERROR((AJ4-AI4)/AI4, 0) -> 0.32362242
A5: (주)이랜드 | B5: SUIZHOU JIAN KNITTING CO.,LTD | C5: 3956850 | D5: 608400 | E5: 6417270 | F5: 864200 | G5: 320550 | H5: 714400 | I5: 732000 | J5: 439850 | K5: 439850 | L5: 4005850 | M5: 144150 | N5: 1080270 | O5: 1753200 | P5: =SUM(C5:I5,K5) -> 14053520 | Q5: =SUM(C5:J5,L5:O5) -> 21036990 | R5: 1219200 | S5: 184800 | T5: 3596590 | U5: 838370 | V5: 992100 | W5: 774750 | X5: 1208400 | Y5: 321250 | AD5: =SUM(R5:AC5) -> 9135460 | AE5: =IF(OR(AD5="", P5=""), 0, IFERROR((AD5-P5)/P5, IF(AD5<>0, 1, 0))) -> -0.34995218 | AF5: =IFERROR(_xlfn.RANK.EQ(AD5, $AD$2:$AD$2064), "") -> 38 | AH5: 주식회사 아성다이소 | AI5: 71400300 | AJ5: 108273450 | AK5: =AJ5-AI5 -> 36873150 | AL5: =IFERROR((AJ5-AI5)/AI5, 0) -> 0.5164285
A6: (주)이랜드 | B6: MIDDM GUOJIMAOYI | C6: 496700 | D6: 1399950 | E6: 4061500 | F6: 4826240 | G6: 1228900 | H6: 711570 | I6: 1772450 | J6: 1094350 | K6: 1014050 | L6: 1023470 | M6: 670900 | N6: 1219150 | O6: 2959280 | P6: =SUM(C6:I6,K6) -> 15511360 | Q6: =SUM(C6:J6,L6:O6) -> 21464460 | R6: 234600 | T6: 222700 | U6: 0 | V6: 0 | W6: 0 | X6: 0 | Y6: 230550 | AD6: =SUM(R6:AC6) -> 687850 | AE6: =IF(OR(AD6="", P6=""), 0, IFERROR((AD6-P6)/P6, IF(AD6<>0, 1, 0))) -> -0.95565508 | AF6: =IFERROR(_xlfn.RANK.EQ(AD6, $AD$2:$AD$2064), "") -> 383 | AH6: (주)건종 | AI6: 77849500 | AJ6: 80551550 | AK6: =AJ6-AI6 -> 2702050 | AL6: =IFERROR((AJ6-AI6)/AI6, 0) -> 0.034708637
A7: (주)이랜드 | B7: WISH TRADING(SHANGHAI) CO., LTD. | C7: 2538200 | D7: 520020 | E7: 3288350 | F7: 1635350 | G7: 2713600 | H7: 2942520 | I7: 3805410 | J7: 3726970 | K7: 2687320 | L7: 1223500 | M7: 1277350 | N7: 5713530 | O7: 3552100 | P7: =SUM(C7:I7,K7) -> 20130770 | Q7: =SUM(C7:J7,L7:O7) -> 32936900 | R7: 1583520 | S7: 308950 | T7: 1850820 | U7: 2516220 | V7: 3759370 | W7: 813070 | X7: 366670 | Y7: 1780720 | AD7: =SUM(R7:AC7) -> 12979340 | AE7: =IF(OR(AD7="", P7=""), 0, IFERROR((AD7-P7)/P7, IF(AD7<>0, 1, 0))) -> -0.35524871 | AF7: =IFERROR(_xlfn.RANK.EQ(AD7, $AD$2:$AD$2064), "") -> 28 | AH7: (주)티비에이치글로벌 | AI7: 68862310 | AJ7: 59896740 | AK7: =AJ7-AI7 -> -8965570 | AL7: =IFERROR((AJ7-AI7)/AI7, 0) -> -0.1301956
A8: (주)이랜드 | B8: NINGBO DONGCHEN | C8: 938800 | D8: 2487300 | E8: 3852600 | F8: 1740050 | G8: 1317900 | H8: 2111720 | I8: 2941600 | J8: 1328650 | K8: 1190800 | L8: 6798040 | M8: 2096540 | N8: 1860570 | O8: 2425650 | P8: =SUM(C8:I8,K8) -> 16580770 | Q8: =SUM(C8:J8,L8:O8) -> 29899420 | R8: 3272820 | S8: 2334850 | T8: 2843050 | U8: 1704800 | V8: 1472580 | W8: 1367470 | X8: 3509500 | Y8: 1924600 | AD8: =SUM(R8:AC8) -> 18429670 | AE8: =IF(OR(AD8="", P8=""), 0, IFERROR((AD8-P8)/P8, IF(AD8<>0, 1, 0))) -> 0.11150869 | AF8: =IFERROR(_xlfn.RANK.EQ(AD8, $AD$2:$AD$2064), "") -> 19 | AH8: (주)에프앤에프_MLB | AI8: 53609440 | AJ8: 56145950 | AK8: =AJ8-AI8 -> 2536510 | AL8: =IFERROR((AJ8-AI8)/AI8, 0) -> 0.047314615
A9: (주)이랜드 | B9: DONGGUAN TIANLAN | C9: 1436950 | D9: 29600 | E9: 4425250 | F9: 955500 | G9: 3433550 | H9: 1910550 | I9: 3258550 | J9: 2899800 | K9: 2899800 | L9: 1373400 | M9: 1043000 | N9: 634080 | O9: 1479850 | P9: =SUM(C9:I9,K9) -> 18349750 | Q9: =SUM(C9:J9,L9:O9) -> 22880080 | R9: 247250 | T9: 2498000 | U9: 2469300 | V9: 203650 | W9: 1918400 | X9: 884950 | Y9: 1512700 | AD9: =SUM(R9:AC9) -> 9734250 | AE9: =IF(OR(AD9="", P9=""), 0, IFERROR((AD9-P9)/P9, IF(AD9<>0, 1, 0))) -> -0.46951593 | AF9: =IFERROR(_xlfn.RANK.EQ(AD9, $AD$2:$AD$2064), "") -> 35 | AH9: 주식회사 무신사 | AI9: 0 | AJ9: 50358540 | AK9: =AJ9-AI9 -> 50358540 | AL9: =IFERROR((AJ9-AI9)/AI9, 0) -> 0
A10: (주)이랜드 | B10: NANTONG YIYUAN | C10: 6318150 | D10: 195750 | E10: 825100 | F10: 1982500 | G10: 885900 | H10: 1129050 | I10: 1443200 | J10: 1561250 | K10: 1493600 | L10: 404100 | M10: 313150 | N10: 531350 | O10: 1017900 | P10: =SUM(C10:I10,K10) -> 14273250 | Q10: =SUM(C10:J10,L10:O10) -> 16607400 | R10: 369800 | S10: 59850 | T10: 549350 | U10: 1299700 | V10: 915090 | W10: 1257400 | X10: 1267900 | Y10: 1082350 | AD10: =SUM(R10:AC10) -> 6801440 | AE10: =IF(OR(AD10="", P10=""), 0, IFERROR((AD10-P10)/P10, IF(AD10<>0, 1, 0))) -> -0.52348344 | AF10: =IFERROR(_xlfn.RANK.EQ(AD10, $AD$2:$AD$2064), "") -> 61 | AH10: (주)에프앤에프_MLB KIDS | AI10: 3332750 | AJ10: 43389500 | AK10: =AJ10-AI10 -> 40056750 | AL10: =IFERROR((AJ10-AI10)/AI10, 0) -> 12.019128
A11: (주)이랜드 | B11: GUANGZHOU WANGFENG | C11: 582150 | D11: 1897020 | E11: 2937950 | F11: 1089370 | G11: 3011390 | H11: 1501520 | I11: 5626100 | J11: 1767900 | K11: 1368150 | L11: 3435690 | M11: 1702000 | N11: 2695900 | O11: 4087800 | P11: =SUM(C11:I11,K11) -> 18013650 | Q11: =SUM(C11:J11,L11:O11) -> 30334790 | R11: 1876470 | S11: 683700 | T11: 3089890 | U11: 1587650 | V11: 999060 | W11: 3932790 | X11: 4096250 | Y11: 2074400 | AD11: =SUM(R11:AC11) -> 18340210 | AE11: =IF(OR(AD11="", P11=""), 0, IFERROR((AD11-P11)/P11, IF(AD11<>0, 1, 0))) -> 0.018128475 | AF11: =IFERROR(_xlfn.RANK.EQ(AD11, $AD$2:$AD$2064), "") -> 20 | AH11: 신성통상(주) | AI11: 22157500 | AJ11: 42550250 | AK11: =AJ11-AI11 -> 20392750 | AL11: =IFERROR((AJ11-AI11)/AI11, 0) -> 0.92035428
A12: (주)이랜드 | B12: JNT INDUSTRIAL CO.,LTD | C12: 2095450 | D12: 842400 | E12: 2177600 | F12: 2419000 | G12: 1467300 | H12: 1159500 | I12: 2497600 | J12: 6047200 | K12: 5318500 | L12: 1830800 | M12: 4143300 | N12: 5799050 | O12: 5732800 | P12: =SUM(C12:I12,K12) -> 17977350 | Q12: =SUM(C12:J12,L12:O12) -> 36212000 | R12: 2291400 | S12: 142100 | T12: 3250600 | U12: 4517400 | V12: 3115600 | W12: 2485000 | X12: 3626550 | Y12: 1391800 | AD12: =SUM(R12:AC12) -> 20820450 | AE12: =IF(OR(AD12="", P12=""), 0, IFERROR((AD12-P12)/P12, IF(AD12<>0, 1, 0))) -> 0.158149 | AF12: =IFERROR(_xlfn.RANK.EQ(AD12, $AD$2:$AD$2064), "") -> 15 | AH12: (주)현대홈쇼핑 | AI12: 26862000 | AJ12: 35432770 | AK12: =AJ12-AI12 -> 8570770 | AL12: =IFERROR((AJ12-AI12)/AI12, 0) -> 0.31906671
A13: (주)이랜드 | B13: NINGBO MUHE | C13: 2738450 | D13: 198917700 | E13: 363020 | F13: 577600 | G13: 58450 | H13: 2404550 | I13: 1599920 | J13: 3186550 | K13: 2363950 | L13: 53300 | M13: 1132000 | N13: 2341600 | O13: 2633050 | P13: =SUM(C13:I13,K13) -> 209023640 | Q13: =SUM(C13:J13,L13:O13) -> 216006190 | R13: 4582500 | S13: 1301200 | T13: 2253000 | U13: 1822000 | V13: 3339120 | W13: 1513350 | X13: 789950 | Y13: 1582050 | AD13: =SUM(R13:AC13) -> 17183170 | AE13: =IF(OR(AD13="", P13=""), 0, IFERROR((AD13-P13)/P13, IF(AD13<>0, 1, 0))) -> -0.91779317 | AF13: =IFERROR(_xlfn.RANK.EQ(AD13, $AD$2:$AD$2064), "") -> 21 | AH13: (주)폰드그룹_어패럴사업부 | AI13: 9480740 | AJ13: 34373050 | AK13: =AJ13-AI13 -> 24892310 | AL13: =IFERROR((AJ13-AI13)/AI13, 0) -> 2.6255661
A14: (주)이랜드 | B14: NINGBOBOLANDIAO | C14: 1375740 | D14: 602450 | E14: 2935600 | F14: 1337250 | G14: 603750 | H14: 413050 | I14: 1141750 | J14: 2627720 | K14: 2627720 | L14: 2229970 | M14: 634050 | N14: 1146170 | O14: 1522850 | P14: =SUM(C14:I14,K14) -> 11037310 | Q14: =SUM(C14:J14,L14:O14) -> 16570350 | R14: 2005350 | S14: 598200 | T14: 4445250 | U14: 1856850 | V14: 644090 | W14: 3195860 | X14: 2759950 | Y14: 3207300 | AD14: =SUM(R14:AC14) -> 18712850 | AE14: =IF(OR(AD14="", P14=""), 0, IFERROR((AD14-P14)/P14, IF(AD14<>0, 1, 0))) -> 0.69541763 | AF14: =IFERROR(_xlfn.RANK.EQ(AD14, $AD$2:$AD$2064), "") -> 18 | AH14: (주)씨제이이엔엠 오쇼핑부문 | AI14: 28752350 | AJ14: 29598250 | AK14: =AJ14-AI14 -> 845900 | AL14: =IFERROR((AJ14-AI14)/AI14, 0) -> 0.029420204
A15: (주)이랜드 | B15: WENZHOU SANTEGA TRADE CO.,LTD | C15: 978100 | D15: 723200 | E15: 1368500 | F15: 1005400 | G15: 2505850 | H15: 1910200 | I15: 3594700 | J15: 4824700 | K15: 4802700 | L15: 2737800 | M15: 318650 | N15: 1911300 | O15: 2370200 | P15: =SUM(C15:I15,K15) -> 16888650 | Q15: =SUM(C15:J15,L15:O15) -> 24248600 | R15: 1418200 | T15: 972050 | U15: 1343500 | V15: 1360750 | W15: 116000 | X15: 1798500 | Y15: 2164000 | AD15: =SUM(R15:AC15) -> 9173000 | AE15: =IF(OR(AD15="", P15=""), 0, IFERROR((AD15-P15)/P15, IF(AD15<>0, 1, 0))) -> -0.45685416 | AF15: =IFERROR(_xlfn.RANK.EQ(AD15, $AD$2:$AD$2064), "") -> 37 | AH15: 주식회사 아성다이소 | AI15: 154000 | AJ15: 25589900 | AK15: =AJ15-AI15 -> 25435900 | AL15: =IFERROR((AJ15-AI15)/AI15, 0) -> 165.16818
A16: (주)이랜드 | B16: GUANGZHOUSHI YASITING FANGZHISHIYEYOUXIANGONGSI | C16: 107750 | D16: 665000 | E16: 3812000 | F16: 1107750 | G16: 724770 | H16: 1042870 | I16: 978200 | J16: 2168250 | K16: 2160800 | L16: 129050 | M16: 1570520 | N16: 3516750 | P16: =SUM(C16:I16,K16) -> 10599140 | Q16: =SUM(C16:J16,L16:O16) -> 15822910 | R16: 28000 | S16: 2704750 | T16: 971900 | U16: 4146750 | V16: 3312570 | W16: 253250 | X16: 4069520 | Y16: 4589150 | AD16: =SUM(R16:AC16) -> 20075890 | AE16: =IF(OR(AD16="", P16=""), 0, IFERROR((AD16-P16)/P16, IF(AD16<>0, 1, 0))) -> 0.89410556 | AF16: =IFERROR(_xlfn.RANK.EQ(AD16, $AD$2:$AD$2064), "") -> 17 | AH16: 지에스리테일 홈쇼핑 | AI16: 25081950 | AJ16: 25208950 | AK16: =AJ16-AI16 -> 127000 | AL16: =IFERROR((AJ16-AI16)/AI16, 0) -> 0.0050634022
A17: (주)이랜드 | B17: YONGDA FANGZHI | C17: 1265150 | D17: 1011150 | E17: 1710300 | F17: 1298800 | G17: 643150 | H17: 306720 | I17: 1014250 | J17: 954350 | K17: 715450 | L17: 3527250 | M17: 2654750 | N17: 1272500 | O17: 403450 | P17: =SUM(C17:I17,K17) -> 7964970 | Q17: =SUM(C17:J17,L17:O17) -> 16061820 | R17: 3476150 | S17: 549670 | T17: 2342820 | U17: 2321110 | V17: 1756500 | W17: 842400 | X17: 2122030 | Y17: 2712780 | AD17: =SUM(R17:AC17) -> 16123460 | AE17: =IF(OR(AD17="", P17=""), 0, IFERROR((AD17-P17)/P17, IF(AD17<>0, 1, 0))) -> 1.0242964 | AF17: =IFERROR(_xlfn.RANK.EQ(AD17, $AD$2:$AD$2064), "") -> 23 | AH17: (주)당당 | AI17: 6961100 | AJ17: 23657000 | AK17: =AJ17-AI17 -> 16695900 | AL17: =IFERROR((AJ17-AI17)/AI17, 0) -> 2.3984571
A18: (주)이랜드 | B18: LEQI GUOJIMAOYI YOUXIANGONGSI | C18: 1041700 | D18: 152250 | E18: 1684750 | F18: 1603420 | G18: 1407500 | H18: 3375040 | I18: 4685810 | J18: 970170 | K18: 731750 | L18: 8150930 | M18: 5246090 | N18: 2405160 | O18: 8320900 | P18: =SUM(C18:I18,K18) -> 14682220 | Q18: =SUM(C18:J18,L18:O18) -> 39043720 | R18: 3949840 | S18: 278900 | T18: 8629150 | U18: 9831400 | V18: 6544610 | W18: 11874320 | X18: 4960340 | Y18: 14924070 | AD18: =SUM(R18:AC18) -> 60992630 | AE18: =IF(OR(AD18="", P18=""), 0, IFERROR((AD18-P18)/P18, IF(AD18<>0, 1, 0))) -> 3.1541831 | AF18: =IFERROR(_xlfn.RANK.EQ(AD18, $AD$2:$AD$2064), "") -> 1 | AH18: 롯데홈쇼핑 | AI18: 27968700 | AJ18: 22375900 | AK18: =AJ18-AI18 -> -5592800 | AL18: =IFERROR((AJ18-AI18)/AI18, 0) -> -0.19996639
A19: (주)이랜드 | B19: ZHONGSHANSHI XIYI | C19: 0 | D19: 0 | E19: 0 | F19: 2516000 | G19: 2782450 | H19: 192450 | I19: 0 | J19: 199450 | K19: 199450 | L19: 0 | M19: 0 | N19: 953650 | O19: 195600 | P19: =SUM(C19:I19,K19) -> 5690350 | Q19: =SUM(C19:J19,L19:O19) -> 6839600 | U19: 665490 | V19: 783550 | W19: 0 | X19: 376400 | Y19: 0 | AD19: =SUM(R19:AC19) -> 1825440 | AE19: =IF(OR(AD19="", P19=""), 0, IFERROR((AD19-P19)/P19, IF(AD19<>0, 1, 0))) -> -0.67920427 | AF19: =IFERROR(_xlfn.RANK.EQ(AD19, $AD$2:$AD$2064), "") -> 225 | AH19: 주식회사 하이드어웨이 | AI19: 0 | AJ19: 21305250 | AK19: =AJ19-AI19 -> 21305250 | AL19: =IFERROR((AJ19-AI19)/AI19, 0) -> 0
A20: (주)이랜드 | B20: NINGBO TONGFU FANGZHI | C20: 1544150 | D20: 0 | E20: 1035710 | F20: 2126870 | G20: 243200 | H20: 307850 | I20: 305850 | J20: 3254330 | K20: 3254330 | L20: 468200 | M20: 1207610 | N20: 509310 | O20: 615170 | P20: =SUM(C20:I20,K20) -> 8817960 | Q20: =SUM(C20:J20,L20:O20) -> 11618250 | R20: 2746180 | S20: 313000 | T20: 1738360 | U20: 284660 | V20: 593580 | W20: 691060 | X20: 1555490 | Y20: 771200 | AD20: =SUM(R20:AC20) -> 8693530 | AE20: =IF(OR(AD20="", P20=""), 0, IFERROR((AD20-P20)/P20, IF(AD20<>0, 1, 0))) -> -0.014110974 | AF20: =IFERROR(_xlfn.RANK.EQ(AD20, $AD$2:$AD$2064), "") -> 42 | AH20: (주)에프앤에프_디스커버리 | AI20: 28991690 | AJ20: 19225820 | AK20: =AJ20-AI20 -> -9765870 | AL20: =IFERROR((AJ20-AI20)/AI20, 0) -> -0.33685066
A21: (주)이랜드 | B21: SUZHOU BOTIAN TEXTILE COMPANY LIMITED | C21: 484850 | D21: 491100 | E21: 1998400 | F21: 495100 | G21: 1292400 | H21: 443450 | I21: 631600 | J21: 337350 | K21: 337350 | L21: 1568800 | M21: 1956450 | N21: 3216850 | O21: 2062150 | P21: =SUM(C21:I21,K21) -> 6174250 | Q21: =SUM(C21:J21,L21:O21) -> 14978500 | R21: 1253200 | S21: 150700 | T21: 265750 | U21: 1900500 | V21: 2170400 | W21: 341800 | X21: 2687950 | Y21: 430900 | AD21: =SUM(R21:AC21) -> 9201200 | AE21: =IF(OR(AD21="", P21=""), 0, IFERROR((AD21-P21)/P21, IF(AD21<>0, 1, 0))) -> 0.49025388 | AF21: =IFERROR(_xlfn.RANK.EQ(AD21, $AD$2:$AD$2064), "") -> 36 | AH21: 휠라코리아(주) | AI21: 48164150 | AJ21: 17185450 | AK21: =AJ21-AI21 -> -30978700 | AL21: =IFERROR((AJ21-AI21)/AI21, 0) -> -0.64319001
